Workbook
Name Slicer_Segregation: #REF!
Name Slicer_Sale_Type: #REF!

Sheet Sales Report
H2: Yens Sales Report
D3: Analysis of Weekly and Monthly Sales Data

Sheet Weekly Sales Data
A6: Week | H6: Week | I6: Market | J6: Shop | K6: Grand Total
A7: 1 | H7: 1 | J7: 17360 | K7: 17360
A8: 2 | H8: 2 | J8: 18800 | K8: 18800
A9: 3 | H9: 3 | J9: 19600 | K9: 19600
A10: 4 | H10: 4 | I10: 5760 | J10: 21512 | K10: 27272
A11: 5 | H11: 5 | J11: 20276 | K11: 20276
A12: 6 | H12: 6 | I12: 13845 | J12: 26236 | K12: 40081
A13: 7 | H13: 7 | I13: 20341 | J13: 25020 | K13: 45361
A14: 8 | H14: 8 | I14: 16340 | J14: 17227 | K14: 33567
A15: 9 | H15: 9 | I15: 15845 | J15: 18989 | K15: 34834
A16: 10 | H16: 10 | J16: 16038 | K16: 16038
A17: 11 | H17: 11 | I17: 16310 | J17: 14389 | K17: 30699
A18: 12 | H18: 12 | I18: 19196 | J18: 17651 | K18: 36847
A19: 13 | H19: 13 | I19: 15570 | J19: 13730 | K19: 29300
A20: 14 | H20: 14 | I20: 31836 | J20: 8568 | K20: 40404
A21: 15 | H21: 15 | I21: 25385 | J21: 11105 | K21: 36490
A22: 16 | H22: 16 | I22: 27078 | J22: 10565 | K22: 37643
A23: 17 | H23: 17 | I23: 19039 | J23: 13268 | K23: 32307
A24: 18 | H24: 18 | I24: 16327 | J24: 14663 | K24: 30990
A25: 19 | H25: 19 | I25: 15067 | J25: 13699 | K25: 28766
H26: Total | I26: 257939 | J26: 318696 | K26: 576635

Sheet Monthly Sales Data

Sheet Daily Monthly Data
A1: DAILY/ MONTH DATA

Sheet Consolidated Data
A1: CONSOLIDATED DATA
A2: FROM JULY 2024 TO NOV 2024 (Incuding Market Data)
K3: =SUBTOTAL(9,K5:K5939) -> 576635
A4: Date | B4: Revised Date | C4: Revised Weekly Data | D4: Receipt number | E4: Order channel | F4: Sale | G4: Quantity | H4: Payment | I4: Discount (฿) | J4: Tip (฿) | K4: Net sales | L4: Sale Type | M4: Market Type | N4: Segregation
A5: 2024-07-24 10:10 | B5: =DATEVALUE(LEFT(A5, 10)) + TIMEVALUE(MID(A5, 12, 5)) -> 45497.424 | C5: =B5-WEEKDAY(B5,2)+1 -> 45495.424 | D5: 1721790594988562568 | E5: POS | F5: 143.00 | G5: 3 | H5: Cash | I5: 0.00 | J5: 0.00 | K5: 143 | L5: Shop | M5: Shop | N5: Shop
A6: 2024-07-24 10:12 | B6: =DATEVALUE(LEFT(A6, 10)) + TIMEVALUE(MID(A6, 12, 5)) -> 45497.425 | C6: =B6-WEEKDAY(B6,2)+1 -> 45495.425 | D6: 1721790714848356243 | E6: POS | F6: 15.00 | G6: 1 | H6: Cash | I6: 0.00 | J6: 0.00 | K6: 15 | L6: Shop | M6: Shop | N6: Shop
A7: 2024-07-24 11:09 | B7: =DATEVALUE(LEFT(A7, 10)) + TIMEVALUE(MID(A7, 12, 5)) -> 45497.465 | C7: =B7-WEEKDAY(B7,2)+1 -> 45495.465 | D7: 1721794137328259749 | E7: POS | F7: 70.00 | G7: 3 | H7: Cash | I7: 0.00 | J7: 0.00 | K7: 70 | L7: Shop | M7: Shop | N7: Shop
A8: 2024-07-24 11:27 | B8: =DATEVALUE(LEFT(A8, 10)) + TIMEVALUE(MID(A8, 12, 5)) -> 45497.477 | C8: =B8-WEEKDAY(B8,2)+1 -> 45495.477 | D8: 1721795169808668625 | E8: POS | F8: 185.00 | G8: 4 | H8: Cash | I8: 0.00 | J8: 0.00 | K8: 185 | L8: Shop | M8: Shop | N8: Shop
A9: 2024-07-24 11:48 | B9: =DATEVALUE(LEFT(A9, 10)) + TIMEVALUE(MID(A9, 12, 5)) -> 45497.492 | C9: =B9-WEEKDAY(B9,2)+1 -> 45495.492 | D9: 1721796191944164702 | E9: POS | F9: 255.00 | G9: 9 | H9: QR Code | I9: 0.00 | J9: 0.00 | K9: 255 | L9: Shop | M9: Shop | N9: Shop
A10: 2024-07-24 13:29 | B10: =DATEVALUE(LEFT(A10, 10)) + TIMEVALUE(MID(A10, 12, 5)) -> 45497.562 | C10: =B10-WEEKDAY(B10,2)+1 -> 45495.562 | D10: 1721801655220424577 | E10: POS | F10: 268.00 | G10: 7 | H10: Cash | I10: 0.00 | J10: 0.00 | K10: 268 | L10: Shop | M10: Shop | N10: Shop
A11: 2024-07-24 13:31 | B11: =DATEVALUE(LEFT(A11, 10)) + TIMEVALUE(MID(A11, 12, 5)) -> 45497.563 | C11: =B11-WEEKDAY(B11,2)+1 -> 45495.563 | D11: 1721802661922321211 | E11: POS | F11: 160.00 | G11: 5 | H11: QR Code | I11: 0.00 | J11: 0.00 | K11: 160 | L11: Shop | M11: Shop | N11: Shop
A12: 2024-07-24 14:00 | B12: =DATEVALUE(LEFT(A12, 10)) + TIMEVALUE(MID(A12, 12, 5)) -> 45497.583 | C12: =B12-WEEKDAY(B12,2)+1 -> 45495.583 | D12: 1721804311012480254 | E12: POS | F12: 223.00 | G12: 3 | H12: QR Code | I12: 0.00 | J12: 0.00 | K12: 223 | L12: Shop | M12: Shop | N12: Shop
A13: 2024-07-24 14:47 | B13: =DATEVALUE(LEFT(A13, 10)) + TIMEVALUE(MID(A13, 12, 5)) -> 45497.616 | C13: =B13-WEEKDAY(B13,2)+1 -> 45495.616 | D13: 1721807104835582824 | E13: POS | F13: 445.00 | G13: 12 | H13: Cash | I13: 0.00 | J13: 0.00 | K13: 445 | L13: Shop | M13: Shop | N13: Shop
A14: 2024-07-24 14:53 | B14: =DATEVALUE(LEFT(A14, 10)) + TIMEVALUE(MID(A14, 12, 5)) -> 45497.62 | C14: =B14-WEEKDAY(B14,2)+1 -> 45495.62 | D14: 1721807537914629771 | E14: POS | F14: 35.00 | G14: 2 | H14: Cash | I14: 0.00 | J14: 0.00 | K14: 35 | L14: Shop | M14: Shop | N14: Shop
A15: 2024-07-24 14:57 | B15: =DATEVALUE(LEFT(A15, 10)) + TIMEVALUE(MID(A15, 12, 5)) -> 45497.623 | C15: =B15-WEEKDAY(B15,2)+1 -> 45495.623 | D15: 1721807719464783194 | E15: POS | F15: 169.00 | G15: 3 | H15: QR Code | I15: 0.00 | J15: 0.00 | K15: 169 | L15: Shop | M15: Shop | N15: Shop
A16: 2024-07-24 15:00 | B16: =DATEVALUE(LEFT(A16, 10)) + TIMEVALUE(MID(A16, 12, 5)) -> 45497.625 | C16: =B16-WEEKDAY(B16,2)+1 -> 45495.625 | D16: 1721807752982612792 | E16: POS | F16: 65.00 | G16: 2 | H16: Cash | I16: 0.00 | J16: 0.00 | K16: 65 | L16: Shop | M16: Shop | N16: Shop
... A3023: 2024-10-01 10:41 | B3023: =DATEVALUE(LEFT(A3023, 10)) + TIMEVALUE(MID(A3023, 12, 5)) -> 45566.445 | C3023: =B3023-WEEKDAY(B3023,2)+1 -> 45565.445 | D3023: 1727754023714711563 | E3023: POS | F3023: 60.00 | G3023: 3 | H3023: Cash | I3023: 0.00 | J3023: 0.00 | K3023: 60 | L3023: Shop | M3023: Shop | N3023: Shop
A3024: 45520 | B3024: =A3024 -> 45520 | C3024: =B3024-WEEKDAY(B3024,2)+1 -> 45516 | K3024: 1770 | L3024: Market | M3024: w | N3024: Walking Street
A3025: 45521 | B3025: =A3025 -> 45521 | C3025: =B3025-WEEKDAY(B3025,2)+1 -> 45516 | K3025: 3990 | L3025: Market | M3025: W | N3025: Walking Street
A3026: 45535 | B3026: =A3026 -> 45535 | C3026: =B3026-WEEKDAY(B3026,2)+1 -> 45530 | K3026: 4760 | L3026: Market | M3026: W | N3026: Walking Street
A3027: 45535 | B3027: =A3027 -> 45535 | C3027: =B3027-WEEKDAY(B3027,2)+1 -> 45530 | K3027: 3815 | L3027: Market | M3027: J | N3027: Army
A3028: 45536 | B3028: =A3028 -> 45536 | C3028: =B3028-WEEKDAY(B3028,2)+1 -> 45530 | K3028: 5270 | L3028: Market | M3028: J | N3028: Army
A3029: 45541 | B3029: =A3029 -> 45541 | C3029: =B3029-WEEKDAY(B3029,2)+1 -> 45537 | K3029: 5867 | L3029: Market | M3029: W | N3029: Walking Street
A3030: 45542 | B3030: =A3030 -> 45542 | C3030: =B3030-WEEKDAY(B3030,2)+1 -> 45537 | K3030: 4210 | L3030: Market | M3030: W | N3030: Walking Street
A3031: 45542 | B3031: =A3031 -> 45542 | C3031: =B3031-WEEKDAY(B3031,2)+1 -> 45537 | K3031: 3550 | L3031: Market | M3031: J | N3031: Army
A3032: 45543 | B3032: =A3032 -> 45543 | C3032: =B3032-WEEKDAY(B3032,2)+1 -> 45537 | K3032: 6714 | L3032: Market | M3032: J | N3032: Army
A3033: 45548 | B3033: =A3033 -> 45548 | C3033: =B3033-WEEKDAY(B3033,2)+1 -> 45544 | K3033: 1120 | L3033: Market | M3033: W | N3033: Walking Street
A3034: 45549 | B3034: =A3034 -> 45549 | C3034: =B3034-WEEKDAY(B3034,2)+1 -> 45544 | K3034: 4250 | L3034: Market | M3034: W | N3034: Walking Street
A3035: 45549 | B3035: =A3035 -> 45549 | C3035: =B3035-WEEKDAY(B3035,2)+1 -> 45544 | K3035: 5510 | L3035: Market | M3035: J | N3035: Army
... A3076: 45619 | B3076: =A3076 -> 45619 | C3076: =B3076-WEEKDAY(B3076,2)+1 -> 45614 | K3076: 2404 | L3076: Market | M3076: W | N3076: Walking Street
A3077: 45620 | B3077: =A3077 -> 45620 | C3077: =B3077-WEEKDAY(B3077,2)+1 -> 45614 | K3077: 0 | L3077: Market | M3077: 0 | N3077: Other Market
A3078: 45621 | B3078: =A3078 -> 45621 | C3078: =B3078-WEEKDAY(B3078,2)+1 -> 45621 | K3078: 5609 | L3078: Market | M3078: D | N3078: Supalai
A3079: 45625 | B3079: =A3079 -> 45625 | C3079: =B3079-WEEKDAY(B3079,2)+1 -> 45621 | K3079: 3188 | L3079: Market | M3079: W | N3079: Walking Street
A3080: 45626 | B3080: =A3080 -> 45626 | C3080: =B3080-WEEKDAY(B3080,2)+1 -> 45621 | K3080: 3692 | L3080: Market | M3080: W | N3080: Walking Street
A3081: 45626 | B3081: =A3081 -> 45626 | C3081: =B3081-WEEKDAY(B3081,2)+1 -> 45621 | K3081: 2578 | L3081: Market | M3081: 0 | N3081: Other Market
A3082: 2024-08-31 21:53 | B3082: =DATEVALUE(LEFT(A3082, 10)) + TIMEVALUE(MID(A3082, 12, 5)) -> 45535.912 | C3082: =B3082-WEEKDAY(B3082,2)+1 -> 45530.912 | D3082: 1725115917677400032 | E3082: POS | F3082: 89.00 | G3082: 3 | H3082: Cash | I3082: 0.00 | J3082: 0.00 | K3082: 89 | L3082: Shop | M3082: Shop | N3082: Shop
A3083: 2024-08-31 21:51 | B3083: =DATEVALUE(LEFT(A3083, 10)) + TIMEVALUE(MID(A3083, 12, 5)) -> 45535.91 | C3083: =B3083-WEEKDAY(B3083,2)+1 -> 45530.91 | D3083: 1725115765021181481 | E3083: POS | F3083: 35.00 | G3083: 1 | H3083: QR Code | I3083: 0.00 | J3083: 0.00 | K3083: 35 | L3083: Shop | M3083: Shop | N3083: Shop
A3084: 2024-08-31 21:46 | B3084: =DATEVALUE(LEFT(A3084, 10)) + TIMEVALUE(MID(A3084, 12, 5)) -> 45535.907 | C3084: =B3084-WEEKDAY(B3084,2)+1 -> 45530.907 | D3084: 1725115569568284320 | E3084: POS | F3084: 35.00 | G3084: 1 | H3084: QR Code | I3084: 0.00 | J3084: 0.00 | K3084: 35 | L3084: Shop | M3084: Shop | N3084: Shop
A3085: 2024-08-31 21:33 | B3085: =DATEVALUE(LEFT(A3085, 10)) + TIMEVALUE(MID(A3085, 12, 5)) -> 45535.898 | C3085: =B3085-WEEKDAY(B3085,2)+1 -> 45530.898 | D3085: 1725114786880699970 | E3085: POS | F3085: 20.00 | G3085: 1 | H3085: QR Code | I3085: 0.00 | J3085: 0.00 | K3085: 20 | L3085: Shop | M3085: Shop | N3085: Shop
A3086: 2024-08-31 21:32 | B3086: =DATEVALUE(LEFT(A3086, 10)) + TIMEVALUE(MID(A3086, 12, 5)) -> 45535.897 | C3086: =B3086-WEEKDAY(B3086,2)+1 -> 45530.897 | D3086: 1725114740183296066 | E3086: POS | F3086: 20.00 | G3086: 1 | H3086: Cash | I3086: 0.00 | J3086: 0.00 | K3086: 20 | L3086: Shop | M3086: Shop | N3086: Shop
...

Sheet Data Jul 2024
A2: Date | B2: Receipt number | C2: Order channel | D2: Sale | E2: Quantity | F2: Payment | G2: Discount (฿) | H2: Tip (฿) | I2: Net sales
A3: 2024-07-31 20:45 | B3: 1722433524305357778 | C3: POS | D3: 45.00 | E3: 2 | F3: QR Code | G3: 0.00 | H3: 0.00 | I3: 45
A4: 2024-07-31 20:38 | B4: 1722433073884598445 | C4: POS | D4: 30.00 | E4: 2 | F4: Cash | G4: 0.00 | H4: 0.00 | I4: 30
A5: 2024-07-31 20:18 | B5: 1722431920007436940 | C5: POS | D5: 40.00 | E5: 2 | F5: Cash | G5: 0.00 | H5: 0.00 | I5: 40
A6: 2024-07-31 20:10 | B6: 1722431400884450467 | C6: POS | D6: 60.00 | E6: 2 | F6: Cash | G6: 0.00 | H6: 0.00 | I6: 60 | M6: เ
A7: 2024-07-31 19:59 | B7: 1722430735951289293 | C7: POS | D7: 29.00 | E7: 1 | F7: QR Code | G7: 0.00 | H7: 0.00 | I7: 29
A8: 2024-07-31 19:52 | B8: 1722430347067845552 | C8: POS | D8: 25.00 | E8: 1 | F8: Cash | G8: 0.00 | H8: 0.00 | I8: 25
A9: 2024-07-31 19:49 | B9: 1722430127066817010 | C9: POS | D9: 30.00 | E9: 2 | F9: Cash | G9: 0.00 | H9: 0.00 | I9: 30
A10: 2024-07-31 19:48 | B10: 1722430062586503125 | C10: POS | D10: 65.00 | E10: 2 | F10: Cash | G10: 0.00 | H10: 0.00 | I10: 65
A11: 2024-07-31 19:41 | B11: 1722429667031804588 | C11: POS | D11: 169.00 | E11: 4 | F11: Cash | G11: 0.00 | H11: 0.00 | I11: 169
A12: 2024-07-31 19:28 | B12: 1722428901551898456 | C12: POS | D12: 44.00 | E12: 2 | F12: Cash | G12: 0.00 | H12: 0.00 | I12: 44
A13: 2024-07-31 19:09 | B13: 1722427561162378306 | C13: POS | D13: 54.00 | E13: 2 | F13: Cash | G13: 0.00 | H13: 0.00 | I13: 54
A14: 2024-07-31 18:58 | B14: 1722427074855774184 | C14: POS | D14: 15.00 | E14: 1 | F14: Cash | G14: 0.00 | H14: 0.00 | I14: 15
A15: 2024-07-31 18:21 | B15: 1722424878604858234 | C15: POS | D15: 15.00 | E15: 1 | F15: QR Code | G15: 0.00 | H15: 0.00 | I15: 15
A16: 2024-07-31 18:18 | B16: 1722424679308771290 | C16: POS | D16: 20.00 | E16: 1 | F16: QR Code | G16: 0.00 | H16: 0.00 | I16: 20
A17: 2024-07-31 17:53 | B17: 1722423179093446909 | C17: POS | D17: 15.00 | E17: 1 | F17: Cash | G17: 0.00 | H17: 0.00 | I17: 15
A18: 2024-07-31 17:52 | B18: 1722422878331705325 | C18: POS | D18: 75.00 | E18: 4 | F18: Cash | G18: 0.00 | H18: 0.00 | I18: 75
... A303: \ | B303: 2024-07-31 | C303: \ | D303: 2779.00 | E303: 87 | F303: \ | G303: 0.00 | H303: 0.00 | I303: 2779

Sheet Data Aug 2024
A1: Date | B1: Receipt number | C1: Order channel | D1: Sale | E1: Quantity | F1: Payment | G1: Discount (฿) | H1: Tip (฿) | I1: Net sales
A2: 2024-08-31 21:53 | B2: 1725115917677400032 | C2: POS | D2: 89.00 | E2: 3 | F2: Cash | G2: 0.00 | H2: 0.00 | I2: 89
A3: 2024-08-31 21:51 | B3: 1725115765021181481 | C3: POS | D3: 35.00 | E3: 1 | F3: QR Code | G3: 0.00 | H3: 0.00 | I3: 35
A4: 2024-08-31 21:46 | B4: 1725115569568284320 | C4: POS | D4: 35.00 | E4: 1 | F4: QR Code | G4: 0.00 | H4: 0.00 | I4: 35
A5: 2024-08-31 21:33 | B5: 1725114786880699970 | C5: POS | D5: 20.00 | E5: 1 | F5: QR Code | G5: 0.00 | H5: 0.00 | I5: 20
A6: 2024-08-31 21:32 | B6: 1725114740183296066 | C6: POS | D6: 20.00 | E6: 1 | F6: Cash | G6: 0.00 | H6: 0.00 | I6: 20
A7: 2024-08-31 21:30 | B7: 1725114580816537517 | C7: POS | D7: 25.00 | E7: 1 | F7: Cash | G7: 0.00 | H7: 0.00 | I7: 25
A8: 2024-08-31 21:29 | B8: 1725114055529728988 | C8: POS | D8: 139.00 | E8: 3 | F8: Cash | G8: 0.00 | H8: 0.00 | I8: 139
A9: 2024-08-31 21:16 | B9: 1725113795217907172 | C9: POS | D9: 35.00 | E9: 2 | F9: Cash | G9: 0.00 | H9: 0.00 | I9: 35
A10: 2024-08-31 21:07 | B10: 1725113211413465834 | C10: POS | D10: 60.00 | E10: 3 | F10: Cash | G10: 0.00 | H10: 0.00 | I10: 60
A11: 2024-08-31 21:00 | B11: 1725112840050928438 | C11: POS | D11: 45.00 | E11: 2 | F11: QR Code | G11: 0.00 | H11: 0.00 | I11: 45
A12: 2024-08-31 20:44 | B12: 1725111190791736882 | C12: POS | D12: 396.00 | E12: 7 | F12: QR Code | G12: 0.00 | H12: 0.00 | I12: 396
A13: 2024-08-31 20:36 | B13: 1725111370386481704 | C13: POS | D13: 60.00 | E13: 2 | F13: Cash | G13: 0.00 | H13: 0.00 | I13: 60
... A1694: \ | B1694: 2024-08-31 | C1694: \ | D1694: 5406.00 | E1694: 176 | F1694: \ | G1694: 0.00 | H1694: 0.00 | I1694: 5406

Sheet Data Sep 2024
A1: Date | B1: Receipt number | C1: Order channel | D1: Sale | E1: Quantity | F1: Payment | G1: Discount (฿) | H1: Tip (฿) | I1: Net sales
A2: 2024-09-30 21:12 | B2: 1727705537409436057 | C2: POS | D2: 45.00 | E2: 1 | F2: Cash | G2: 0.00 | H2: 0.00 | I2: 45 | J2: 45
A3: 2024-09-30 21:11 | B3: 1727705471807920415 | C3: POS | D3: 25.00 | E3: 1 | F3: QR Code | G3: 0.00 | H3: 0.00 | I3: 25 | J3: 25
A4: 2024-09-30 20:57 | B4: 1727704603897207669 | C4: POS | D4: 45.00 | E4: 1 | F4: QR Code | G4: 0.00 | H4: 0.00 | I4: 45 | J4: 45
A5: 2024-09-30 20:25 | B5: 1727702748933116338 | C5: POS | D5: 45.00 | E5: 2 | F5: Cash | G5: 0.00 | H5: 0.00 | I5: 45 | J5: 45
A6: 2024-09-30 20:24 | B6: 1727702684633764751 | C6: POS | D6: 35.00 | E6: 2 | F6: Cash | G6: 0.00 | H6: 0.00 | I6: 35 | J6: 35
A7: 2024-09-30 20:03 | B7: 1727701408790499721 | C7: POS | D7: 20.00 | E7: 1 | F7: QR Code | G7: 0.00 | H7: 0.00 | I7: 20 | J7: 20
A8: 2024-09-30 19:26 | B8: 1727699165747185023 | C8: POS | D8: 80.00 | E8: 2 | F8: QR Code | G8: 0.00 | H8: 0.00 | I8: 80 | J8: 80
A9: 2024-09-30 19:20 | B9: 1727698831380309085 | C9: POS | D9: 45.00 | E9: 2 | F9: QR Code | G9: 0.00 | H9: 0.00 | I9: 45 | J9: 45
A10: 2024-09-30 19:20 | B10: 1727698808745508986 | C10: POS | D10: 69.00 | E10: 2 | F10: Cash | G10: 0.00 | H10: 0.00 | I10: 69 | J10: 69
A11: 2024-09-30 19:13 | B11: 1727698401333262152 | C11: POS | D11: 15.00 | E11: 1 | F11: Cash | G11: 0.00 | H11: 0.00 | I11: 15 | J11: 15
A12: 2024-09-30 18:00 | B12: 1727693904910812962 | C12: POS | D12: 105.00 | E12: 3 | F12: QR Code | G12: 0.00 | H12: 0.00 | I12: 105 | J12: 105
A13: 2024-09-30 17:11 | B13: 1727691078507427443 | C13: POS | D13: 40.00 | E13: 2 | F13: Cash | G13: 0.00 | H13: 0.00 | I13: 40 | J13: 40
... A1538: 2024-09-01 10:32 | B1538: 1725161506593533474 | C1538: POS | D1538: 20.00 | E1538: 1 | F1538: Cash | G1538: 0.00 | H1538: 0.00 | I1538: 20 | J1538: 20
A1539: \ | B1539: รวมทั้งหมด | C1539: \ | D1539: 82598.00 | E1539: 2984 | F1539: \ | G1539: -748.00 | H1539: 0.00 | I1539: 82598
A1540: \ | B1540: 2024-09-01 | C1540: \ | D1540: 4121.00 | E1540: 138 | F1540: \ | G1540: 0.00 | H1540: 0.00 | I1540: 4121
A1541: \ | B1541: 2024-09-02 | C1541: \ | D1541: 3648.00 | E1541: 126 | F1541: \ | G1541: 0.00 | H1541: 0.00 | I1541: 3648
A1542: \ | B1542: 2024-09-03 | C1542: \ | D1542: 3638.00 | E1542: 121 | F1542: \ | G1542: 0.00 | H1542: 0.00 | I1542: 3638
A1543: \ | B1543: 2024-09-04 | C1543: \ | D1543: 3129.00 | E1543: 121 | F1543: \ | G1543: 0.00 | H1543: 0.00 | I1543: 3129
A1544: \ | B1544: 2024-09-05 | C1544: \ | D1544: 3196.00 | E1544: 104 | F1544: \ | G1544: 0.00 | H1544: 0.00 | I1544: 3196
A1545: \ | B1545: 2024-09-06 | C1545: \ | D1545: 4170.00 | E1545: 137 | F1545: \ | G1545: 0.00 | H1545: 0.00 | I1545: 4170
A1546: \ | B1546: 2024-09-07 | C1546: \ | D1546: 3195.00 | E1546: 120 | F1546: \ | G1546: 0.00 | H1546: 0.00 | I1546: 3195
A1547: \ | B1547: 2024-09-08 | C1547: \ | D1547: 4044.00 | E1547: 152 | F1547: \ | G1547: 0.00 | H1547: 0.00 | I1547: 4044
A1548: \ | B1548: 2024-09-09 | C1548: \ | D1548: 2987.00 | E1548: 113 | F1548: \ | G1548: -154.00 | H1548: 0.00 | I1548: 2987
A1549: \ | B1549: 2024-09-10 | C1549: \ | D1549: 2390.00 | E1549: 93 | F1549: \ | G1549: -132.00 | H1549: 0.00 | I1549: 2390
A1550: \ | B1550: 2024-09-11 | C1550: \ | D1550: 2023.00 | E1550: 80 | F1550: \ | G1550: -88.00 | H1550: 0.00 | I1550: 2023
... A1569: \ | B1569: 2024-09-30 | C1569: \ | D1569: 1203.00 | E1569: 43 | F1569: \ | G1569: 0.00 | H1569: 0.00 | I1569: 1203

Sheet Data Oct 2024
A1: Date | B1: Receipt number | C1: Order channel | D1: Sale | E1: Quantity | F1: Payment | G1: Discount (฿) | H1: Tip (฿) | I1: Net sales
A2: 2024-10-31 21:19 | B2: 1730384358506760375 | C2: POS | D2: 15.00 | E2: 1 | F2: QR Code | G2: 0.00 | H2: 0.00 | I2: 15
A3: 2024-10-31 20:53 | B3: 1730382792062720399 | C3: POS | D3: 15.00 | E3: 1 | F3: QR Code | G3: 0.00 | H3: 0.00 | I3: 15
A4: 2024-10-31 20:24 | B4: 1730381063519819800 | C4: POS | D4: 69.00 | E4: 2 | F4: Cash | G4: 0.00 | H4: 0.00 | I4: 69
A5: 2024-10-31 20:19 | B5: 1730380727645336303 | C5: POS | D5: 39.00 | E5: 1 | F5: Cash | G5: 0.00 | H5: 0.00 | I5: 39
A6: 2024-10-31 20:18 | B6: 1730380697367733726 | C6: POS | D6: 49.00 | E6: 1 | F6: Cash | G6: 0.00 | H6: 0.00 | I6: 49
A7: 2024-10-31 20:15 | B7: 1730380545604844597 | C7: POS | D7: 108.00 | E7: 2 | F7: QR Code | G7: 0.00 | H7: 0.00 | I7: 108
A8: 2024-10-31 20:03 | B8: 1730379785974765447 | C8: POS | D8: 45.00 | E8: 2 | F8: Cash | G8: 0.00 | H8: 0.00 | I8: 45
A9: 2024-10-31 19:58 | B9: 1730379481380171311 | C9: POS | D9: 15.00 | E9: 1 | F9: Cash | G9: 0.00 | H9: 0.00 | I9: 15
A10: 2024-10-31 19:51 | B10: 1730379068536239515 | C10: POS | D10: 40.00 | E10: 1 | F10: QR Code | G10: 0.00 | H10: 0.00 | I10: 40
A11: 2024-10-31 18:59 | B11: 1730375799661217389 | C11: POS | D11: 65.00 | E11: 2 | F11: Cash | G11: 0.00 | H11: 0.00 | I11: 65
A12: 2024-10-31 18:19 | B12: 1730373593613488892 | C12: POS | D12: 20.00 | E12: 1 | F12: Cash | G12: 0.00 | H12: 0.00 | I12: 20
A13: 2024-10-31 17:59 | B13: 1730372390340618012 | C13: POS | D13: 35.00 | E13: 2 | F13: QR Code | G13: 0.00 | H13: 0.00 | I13: 35
... A1221: \ | B1221: 2024-10-31 | C1221: \ | D1221: 1121.00 | E1221: 39 | F1221: \ | G1221: 0.00 | H1221: 0.00 | I1221: 1121

Sheet Data Nov 2024
A1: Date | B1: Receipt number | C1: Order channel | D1: Sale | E1: Quantity | F1: Payment | G1: Discount (฿) | H1: Tip (฿) | I1: Net sales
A2: 2024-11-30 21:55 | B2: 1732978532558398087 | C2: POS | D2: 70.00 | E2: 2 | F2: QR Code | G2: 0.00 | H2: 0.00 | I2: 70
A3: 2024-11-30 21:51 | B3: 1732978250341844014 | C3: POS | D3: 80.00 | E3: 2 | F3: QR Code | G3: 0.00 | H3: 0.00 | I3: 80
A4: 2024-11-30 21:44 | B4: 1732977819794285266 | C4: POS | D4: 40.00 | E4: 1 | F4: Cash | G4: 0.00 | H4: 0.00 | I4: 40
A5: 2024-11-30 21:32 | B5: 1732977144001417705 | C5: POS | D5: 30.00 | E5: 2 | F5: QR Code | G5: 0.00 | H5: 0.00 | I5: 30
A6: 2024-11-30 21:20 | B6: 1732976388771484955 | C6: POS | D6: 20.00 | E6: 1 | F6: QR Code | G6: 0.00 | H6: 0.00 | I6: 20
A7: 2024-11-30 21:18 | B7: 1732976264916666181 | C7: POS | D7: 25.00 | E7: 1 | F7: Cash | G7: 0.00 | H7: 0.00 | I7: 25
A8: 2024-11-30 20:50 | B8: 1732974625723830815 | C8: POS | D8: 99.00 | E8: 2 | F8: Cash | G8: 0.00 | H8: 0.00 | I8: 99
A9: 2024-11-30 20:49 | B9: 1732974395718826176 | C9: POS | D9: 55.00 | E9: 2 | F9: QR Code | G9: 0.00 | H9: 0.00 | I9: 55
A10: 2024-11-30 20:41 | B10: 1732974056083242433 | C10: POS | D10: 30.00 | E10: 2 | F10: Cash | G10: 0.00 | H10: 0.00 | I10: 30
A11: 2024-11-30 19:46 | B11: 1732970788923127719 | C11: POS | D11: 55.00 | E11: 3 | F11: Cash | G11: 0.00 | H11: 0.00 | I11: 55
A12: 2024-11-30 19:45 | B12: 1732970711014410412 | C12: POS | D12: 40.00 | E12: 1 | F12: Cash | G12: 0.00 | H12: 0.00 | I12: 40
A13: 2024-11-30 19:12 | B13: 1732968749278426499 | C13: POS | D13: 25.00 | E13: 1 | F13: Cash | G13: 0.00 | H13: 0.00 | I13: 25
... A1229: \ | B1229: 2024-11-30 | C1229: \ | D1229: 1606.00 | E1229: 58 | F1229: \ | G1229: 0.00 | H1229: 0.00 | I1229: 1606

Sheet MARKET
A1: DATE | B1: CASH | C1: SCAN | D1: EXPENSE | E1: SALE | F1: SHOP | H1: ss
A2: 45520 | B2: 1025 | C2: 705 | D2: 40 | E2: =SUM(B2:D2) -> 1770 | F2: W | G2: 1770 | H2: =E2-G2 -> 0
A3: 45521 | B3: 2165 | C3: 1705 | D3: 120 | E3: =SUM(B3:D3) -> 3990 | F3: W | G3: 3990 | H3: =E3-G3 -> 0
A4: 45535 | B4: 2590 | C4: 1920 | D4: 250 | E4: =SUM(B4:D4) -> 4760 | F4: W | G4: 4760 | H4: =E4-G4 -> 0
A5: 45535 | B5: 2485 | C5: 875 | D5: 455 | E5: =SUM(B5:D5) -> 3815 | F5: J | G5: 3815 | H5: =E5-G5 -> 0
A6: 45536 | B6: 3795 | C6: 1095 | D6: 380 | E6: =SUM(B6:D6) -> 5270 | F6: J | G6: 5270 | H6: =E6-G6 -> 0
A7: 45541 | B7: 3227 | C7: 2360 | D7: 280 | E7: =SUM(B7:D7) -> 5867 | F7: W | G7: 5867 | H7: =E7-G7 -> 0
A8: 45542 | B8: 2400 | C8: 1570 | D8: 240 | E8: =SUM(B8:D8) -> 4210 | F8: W | G8: 4210 | H8: =E8-G8 -> 0
A9: 45542 | B9: 2315 | C9: 645 | D9: 590 | E9: =SUM(B9:D9) -> 3550 | F9: J | G9: 3550 | H9: =E9-G9 -> 0
A10: 45543 | B10: 4277 | C10: 1845 | D10: 592 | E10: =SUM(B10:D10) -> 6714 | F10: J | G10: 6714 | H10: =E10-G10 -> 0
A11: 45548 | B11: 305 | C11: 495 | D11: 320 | E11: =SUM(B11:D11) -> 1120 | F11: W | G11: 1120 | H11: =E11-G11 -> 0
A12: 45549 | B12: 2505 | C12: 1530 | D12: 215 | E12: =SUM(B12:D12) -> 4250 | F12: W | G12: 4250 | H12: =E12-G12 -> 0
A13: 45549 | B13: 3765 | C13: 1220 | D13: 525 | E13: =SUM(B13:D13) -> 5510 | F13: J | G13: 5510 | H13: =E13-G13 -> 0
... A53: 45619 | B53: 3028 | C53: 1329 | D53: 531 | E53: =SUM(B53:D53) -> 4888 | F53: J | G53: 4888 | H53: =E53-G53 -> 0
A54: 45619 | B54: 2194 | D54: 210 | E54: =SUM(B54:D54) -> 2404 | F54: W | G54: 2404 | H54: =E54-G54 -> 0
A55: 45620 | E55: =SUM(B55:D55) -> 0 | G55: 0 | H55: =E55-G55 -> 0
A56: 45621 | B56: 3697 | C56: 1712 | D56: 200 | E56: =SUM(B56:D56) -> 5609 | F56: D | G56: 5609 | H56: =E56-G56 -> 0
A57: 45625 | B57: 1514 | C57: 1344 | D57: 330 | E57: =SUM(B57:D57) -> 3188 | F57: W | G57: 3188 | H57: =E57-G57 -> 0
A58: 45626 | B58: 1665 | C58: 1827 | D58: 200 | E58: =SUM(B58:D58) -> 3692 | F58: W | G58: 3692 | H58: =E58-G58 -> 0
A59: 45626 | B59: 1280 | C59: 703 | D59: 595 | E59: =SUM(B59:D59) -> 2578 | G59: 2578 | H59: =E59-G59 -> 0
E63: =SUM(E2:E59) -> 257939
